Workbook

Sheet 00_README
A1: Svensk Frilans Ekonomi Pack — README
A3: Field | B3: Value
A4: Version | B4: 1.0 — AI Race product build
A5: Purpose | B5: Practical cash control for Swedish freelancers / egenanställda
A6: Not | B6: Not bookkeeping software. Not tax advice. Not a substitute for Bokio/Fortnox/accountant.
A7: Legal note | B7: Swedish bookkeeping law requires immutable bookkeeping systems; Excel is for planning/logs only.
A8: Sheets | B8: Setup · Fee_Catalog · Pricing · Income_Log · Expense_Log · Cashflow · Invoice_Log · Tax_Estimate · Dashboard
A9: How to use | B9: 1) Fill Setup. 2) Log income/expenses. 3) Price jobs in Pricing. 4) Review Dashboard weekly.
A10: Google Sheets | B10: File → Import → Upload this .xlsx → Replace spreadsheet.
A11: Currency | B11: SEK throughout
A12: Support | B12: Product includes formulas only; update fee rates if platforms change.

Sheet 01_Setup
A1: Setup — your defaults
A3: Setting | B3: Value | C3: Notes
A4: Display name | B4: Ditt namn | C4: Shown on invoice log exports
A5: Default platform | B5: Direktkund | C5: Direktkund / Frilans Finans / Fiverr / Gumroad / Annat
A6: Default hourly target SEK | B6: 650 | C6: What you want to earn per effective hour before platform fees
A7: Target net monthly SEK | B7: 25000 | C7: After rough tax estimate — planning only
A8: Illustrative income tax % | B8: 0.3 | C8: Rough personal planning rate — replace with your own estimate
A9: Employer fee / social approx % | B9: 0.3142 | C9: Relevant when comparing egenanställning gross invoice vs net
A10: Frilans Finans fee % | B10: 0.06 | C10: Update if your plan differs
A11: Fiverr fee % | B11: 0.2 | C11: Seller commission
A12: Gumroad fee % | B12: 0.1 | C12: Approx platform fee; processing may differ
A13: Payhip free fee % | B13: 0.05 | C13: Plus separate Stripe/PayPal processing outside this model
A14: VAT registered? | B14: Nej | C14: Ja/Nej — if Ja, use 25% on eligible sales in Pricing
A15: Default VAT % | B15: 0.25 | C15: Standard Swedish moms
A16: Starting cash SEK | B16: 200 | C16: Optional opening balance for Cashflow
A17: Race / project tag | B17: AI-Race | C17: Optional label
A20: Named ranges used by other sheets read these B cells directly.

Sheet 02_Fee_Catalog
A1: Fee catalog — edit rates when platforms change
A3: Platform | B3: Fee % | C3: Settlement note | D3: Typical payout lag | E3: Source / checked
A4: Direktkund / Swish | B4: 0 | C4: Direct payment | D4: Immediate–1 day | E4: Frilans Finans Swish docs
A5: Frilans Finans invoice | B5: 0.06 | C5: Gross invoice fee before tax/employer charges | D5: ≈5 bank days salary | E5: frilansfinans.se 2026
A6: Fiverr | B6: 0.2 | C6: Seller commission on order value | D6: 14 days after completion (new sellers) | E6: Fiverr Help 2026
A7: Gumroad | B7: 0.1 | C7: Platform fee; payout holds apply | D7: 7-day hold + weekly payout; new-account review | E7: gumroad.com/help 2026
A8: Payhip Free | B8: 0.05 | C8: Plus Stripe/PayPal processing separately | D8: Processor-connected / often fast | E8: Payhip pricing pages 2026
A9: Etsy digital | B9: 0.065 | C9: Plus listing $0.20 + processing | D9: New seller holds possible | E9: Etsy fee guides 2026
A10: Upwork | B10: 0.1 | C10: Varies by contract history | D10: Platform withdrawal rules | E10: Verify before quoting

Sheet 03_Pricing
A1: Job pricing calculator — quote with fees in mind
A3: Field | B3: Value | D3: Quick quote presets (edit freely)
A4: Job name | B4: Landing page — Basic | D4: Offer | E4: Hours | F4: List price SEK
A5: Estimated hours | B5: 6 | D5: Webbfix Mini | E5: 2 | F5: 499
A6: Hourly target SEK | B6: ='01_Setup'!B6 | D6: Landing Basic | E6: 6 | F6: 999
A7: Desired net to you SEK | B7: =B5*B6 | D7: Landing Pro | E7: 12 | F7: 1799
A8: Platform | B8: Frilans Finans | D8: Sheet automation | E8: 4 | F8: 799
A9: Platform fee % | B9: =IF(B8="Fiverr",'01_Setup'!B11,IF(B8="Gumroad",'01_Setup'!B12,IF(B8="Payhip",'01_Setup'!B13,IF(B8="Frilans Finans",'01_Setup'!B10,0)))) | D9: Digital product | E9: 0 | F9: 149
A10: VAT applicable? | B10: ='01_Setup'!B14
A11: VAT % | B11: =IF(B10="Ja",'01_Setup'!B15,0)
A13: Output | B13: SEK / value
A14: Gross to charge before VAT | B14: =IF((1-B9)=0,0,B7/(1-B9))
A15: Platform fee SEK | B15: =B14*B9
A16: VAT SEK | B16: =B14*B11
A17: Customer pays (incl VAT) | B17: =B14+B16
A18: You keep before income tax (approx) | B18: =B14-B15
A19: Illustrative after income tax | B19: =B18*(1-'01_Setup'!B8)
A20: Effective hourly after platform fee | B20: =IF(B5=0,0,B18/B5)

Sheet 04_Income_Log
A1: Income log — settled and pending
A3: Date | B3: Client / source | C3: Description | D3: Platform | E3: Gross SEK | F3: Fee % | G3: Fee SEK | H3: Net SEK | I3: Status | J3: Settled date | K3: Evidence ref | L3: Notes
F4: =IF(D4="","",IF(D4="Fiverr",'01_Setup'!B11,IF(D4="Gumroad",'01_Setup'!B12,IF(D4="Payhip",'01_Setup'!B13,IF(D4="Frilans Finans",'01_Setup'!B10,0))))) | G4: =IF(E4="","",E4*F4) | H4: =IF(E4="","",E4-G4)
F5: =IF(D5="","",IF(D5="Fiverr",'01_Setup'!B11,IF(D5="Gumroad",'01_Setup'!B12,IF(D5="Payhip",'01_Setup'!B13,IF(D5="Frilans Finans",'01_Setup'!B10,0))))) | G5: =IF(E5="","",E5*F5) | H5: =IF(E5="","",E5-G5)
F6: =IF(D6="","",IF(D6="Fiverr",'01_Setup'!B11,IF(D6="Gumroad",'01_Setup'!B12,IF(D6="Payhip",'01_Setup'!B13,IF(D6="Frilans Finans",'01_Setup'!B10,0))))) | G6: =IF(E6="","",E6*F6) | H6: =IF(E6="","",E6-G6)
F7: =IF(D7="","",IF(D7="Fiverr",'01_Setup'!B11,IF(D7="Gumroad",'01_Setup'!B12,IF(D7="Payhip",'01_Setup'!B13,IF(D7="Frilans Finans",'01_Setup'!B10,0))))) | G7: =IF(E7="","",E7*F7) | H7: =IF(E7="","",E7-G7)
F8: =IF(D8="","",IF(D8="Fiverr",'01_Setup'!B11,IF(D8="Gumroad",'01_Setup'!B12,IF(D8="Payhip",'01_Setup'!B13,IF(D8="Frilans Finans",'01_Setup'!B10,0))))) | G8: =IF(E8="","",E8*F8) | H8: =IF(E8="","",E8-G8)
F9: =IF(D9="","",IF(D9="Fiverr",'01_Setup'!B11,IF(D9="Gumroad",'01_Setup'!B12,IF(D9="Payhip",'01_Setup'!B13,IF(D9="Frilans Finans",'01_Setup'!B10,0))))) | G9: =IF(E9="","",E9*F9) | H9: =IF(E9="","",E9-G9)
F10: =IF(D10="","",IF(D10="Fiverr",'01_Setup'!B11,IF(D10="Gumroad",'01_Setup'!B12,IF(D10="Payhip",'01_Setup'!B13,IF(D10="Frilans Finans",'01_Setup'!B10,0))))) | G10: =IF(E10="","",E10*F10) | H10: =IF(E10="","",E10-G10)
F11: =IF(D11="","",IF(D11="Fiverr",'01_Setup'!B11,IF(D11="Gumroad",'01_Setup'!B12,IF(D11="Payhip",'01_Setup'!B13,IF(D11="Frilans Finans",'01_Setup'!B10,0))))) | G11: =IF(E11="","",E11*F11) | H11: =IF(E11="","",E11-G11)
F12: =IF(D12="","",IF(D12="Fiverr",'01_Setup'!B11,IF(D12="Gumroad",'01_Setup'!B12,IF(D12="Payhip",'01_Setup'!B13,IF(D12="Frilans Finans",'01_Setup'!B10,0))))) | G12: =IF(E12="","",E12*F12) | H12: =IF(E12="","",E12-G12)
F13: =IF(D13="","",IF(D13="Fiverr",'01_Setup'!B11,IF(D13="Gumroad",'01_Setup'!B12,IF(D13="Payhip",'01_Setup'!B13,IF(D13="Frilans Finans",'01_Setup'!B10,0))))) | G13: =IF(E13="","",E13*F13) | H13: =IF(E13="","",E13-G13)
F14: =IF(D14="","",IF(D14="Fiverr",'01_Setup'!B11,IF(D14="Gumroad",'01_Setup'!B12,IF(D14="Payhip",'01_Setup'!B13,IF(D14="Frilans Finans",'01_Setup'!B10,0))))) | G14: =IF(E14="","",E14*F14) | H14: =IF(E14="","",E14-G14)
F15: =IF(D15="","",IF(D15="Fiverr",'01_Setup'!B11,IF(D15="Gumroad",'01_Setup'!B12,IF(D15="Payhip",'01_Setup'!B13,IF(D15="Frilans Finans",'01_Setup'!B10,0))))) | G15: =IF(E15="","",E15*F15) | H15: =IF(E15="","",E15-G15)
F16: =IF(D16="","",IF(D16="Fiverr",'01_Setup'!B11,IF(D16="Gumroad",'01_Setup'!B12,IF(D16="Payhip",'01_Setup'!B13,IF(D16="Frilans Finans",'01_Setup'!B10,0))))) | G16: =IF(E16="","",E16*F16) | H16: =IF(E16="","",E16-G16)
F17: =IF(D17="","",IF(D17="Fiverr",'01_Setup'!B11,IF(D17="Gumroad",'01_Setup'!B12,IF(D17="Payhip",'01_Setup'!B13,IF(D17="Frilans Finans",'01_Setup'!B10,0))))) | G17: =IF(E17="","",E17*F17) | H17: =IF(E17="","",E17-G17)
F18: =IF(D18="","",IF(D18="Fiverr",'01_Setup'!B11,IF(D18="Gumroad",'01_Setup'!B12,IF(D18="Payhip",'01_Setup'!B13,IF(D18="Frilans Finans",'01_Setup'!B10,0))))) | G18: =IF(E18="","",E18*F18) | H18: =IF(E18="","",E18-G18)
F19: =IF(D19="","",IF(D19="Fiverr",'01_Setup'!B11,IF(D19="Gumroad",'01_Setup'!B12,IF(D19="Payhip",'01_Setup'!B13,IF(D19="Frilans Finans",'01_Setup'!B10,0))))) | G19: =IF(E19="","",E19*F19) | H19: =IF(E19="","",E19-G19)
F20: =IF(D20="","",IF(D20="Fiverr",'01_Setup'!B11,IF(D20="Gumroad",'01_Setup'!B12,IF(D20="Payhip",'01_Setup'!B13,IF(D20="Frilans Finans",'01_Setup'!B10,0))))) | G20: =IF(E20="","",E20*F20) | H20: =IF(E20="","",E20-G20)
F21: =IF(D21="","",IF(D21="Fiverr",'01_Setup'!B11,IF(D21="Gumroad",'01_Setup'!B12,IF(D21="Payhip",'01_Setup'!B13,IF(D21="Frilans Finans",'01_Setup'!B10,0))))) | G21: =IF(E21="","",E21*F21) | H21: =IF(E21="","",E21-G21)
F22: =IF(D22="","",IF(D22="Fiverr",'01_Setup'!B11,IF(D22="Gumroad",'01_Setup'!B12,IF(D22="Payhip",'01_Setup'!B13,IF(D22="Frilans Finans",'01_Setup'!B10,0))))) | G22: =IF(E22="","",E22*F22) | H22: =IF(E22="","",E22-G22)
F23: =IF(D23="","",IF(D23="Fiverr",'01_Setup'!B11,IF(D23="Gumroad",'01_Setup'!B12,IF(D23="Payhip",'01_Setup'!B13,IF(D23="Frilans Finans",'01_Setup'!B10,0))))) | G23: =IF(E23="","",E23*F23) | H23: =IF(E23="","",E23-G23)
F24: =IF(D24="","",IF(D24="Fiverr",'01_Setup'!B11,IF(D24="Gumroad",'01_Setup'!B12,IF(D24="Payhip",'01_Setup'!B13,IF(D24="Frilans Finans",'01_Setup'!B10,0))))) | G24: =IF(E24="","",E24*F24) | H24: =IF(E24="","",E24-G24)
F25: =IF(D25="","",IF(D25="Fiverr",'01_Setup'!B11,IF(D25="Gumroad",'01_Setup'!B12,IF(D25="Payhip",'01_Setup'!B13,IF(D25="Frilans Finans",'01_Setup'!B10,0))))) | G25: =IF(E25="","",E25*F25) | H25: =IF(E25="","",E25-G25)
F26: =IF(D26="","",IF(D26="Fiverr",'01_Setup'!B11,IF(D26="Gumroad",'01_Setup'!B12,IF(D26="Payhip",'01_Setup'!B13,IF(D26="Frilans Finans",'01_Setup'!B10,0))))) | G26: =IF(E26="","",E26*F26) | H26: =IF(E26="","",E26-G26)
F27: =IF(D27="","",IF(D27="Fiverr",'01_Setup'!B11,IF(D27="Gumroad",'01_Setup'!B12,IF(D27="Payhip",'01_Setup'!B13,IF(D27="Frilans Finans",'01_Setup'!B10,0))))) | G27: =IF(E27="","",E27*F27) | H27: =IF(E27="","",E27-G27)
F28: =IF(D28="","",IF(D28="Fiverr",'01_Setup'!B11,IF(D28="Gumroad",'01_Setup'!B12,IF(D28="Payhip",'01_Setup'!B13,IF(D28="Frilans Finans",'01_Setup'!B10,0))))) | G28: =IF(E28="","",E28*F28) | H28: =IF(E28="","",E28-G28)
F29: =IF(D29="","",IF(D29="Fiverr",'01_Setup'!B11,IF(D29="Gumroad",'01_Setup'!B12,IF(D29="Payhip",'01_Setup'!B13,IF(D29="Frilans Finans",'01_Setup'!B10,0))))) | G29: =IF(E29="","",E29*F29) | H29: =IF(E29="","",E29-G29)
F30: =IF(D30="","",IF(D30="Fiverr",'01_Setup'!B11,IF(D30="Gumroad",'01_Setup'!B12,IF(D30="Payhip",'01_Setup'!B13,IF(D30="Frilans Finans",'01_Setup'!B10,0))))) | G30: =IF(E30="","",E30*F30) | H30: =IF(E30="","",E30-G30)
F31: =IF(D31="","",IF(D31="Fiverr",'01_Setup'!B11,IF(D31="Gumroad",'01_Setup'!B12,IF(D31="Payhip",'01_Setup'!B13,IF(D31="Frilans Finans",'01_Setup'!B10,0))))) | G31: =IF(E31="","",E31*F31) | H31: =IF(E31="","",E31-G31)
F32: =IF(D32="","",IF(D32="Fiverr",'01_Setup'!B11,IF(D32="Gumroad",'01_Setup'!B12,IF(D32="Payhip",'01_Setup'!B13,IF(D32="Frilans Finans",'01_Setup'!B10,0))))) | G32: =IF(E32="","",E32*F32) | H32: =IF(E32="","",E32-G32)
F33: =IF(D33="","",IF(D33="Fiverr",'01_Setup'!B11,IF(D33="Gumroad",'01_Setup'!B12,IF(D33="Payhip",'01_Setup'!B13,IF(D33="Frilans Finans",'01_Setup'!B10,0))))) | G33: =IF(E33="","",E33*F33) | H33: =IF(E33="","",E33-G33)
F34: =IF(D34="","",IF(D34="Fiverr",'01_Setup'!B11,IF(D34="Gumroad",'01_Setup'!B12,IF(D34="Payhip",'01_Setup'!B13,IF(D34="Frilans Finans",'01_Setup'!B10,0))))) | G34: =IF(E34="","",E34*F34) | H34: =IF(E34="","",E34-G34)
F35: =IF(D35="","",IF(D35="Fiverr",'01_Setup'!B11,IF(D35="Gumroad",'01_Setup'!B12,IF(D35="Payhip",'01_Setup'!B13,IF(D35="Frilans Finans",'01_Setup'!B10,0))))) | G35: =IF(E35="","",E35*F35) | H35: =IF(E35="","",E35-G35)
F36: =IF(D36="","",IF(D36="Fiverr",'01_Setup'!B11,IF(D36="Gumroad",'01_Setup'!B12,IF(D36="Payhip",'01_Setup'!B13,IF(D36="Frilans Finans",'01_Setup'!B10,0))))) | G36: =IF(E36="","",E36*F36) | H36: =IF(E36="","",E36-G36)
F37: =IF(D37="","",IF(D37="Fiverr",'01_Setup'!B11,IF(D37="Gumroad",'01_Setup'!B12,IF(D37="Payhip",'01_Setup'!B13,IF(D37="Frilans Finans",'01_Setup'!B10,0))))) | G37: =IF(E37="","",E37*F37) | H37: =IF(E37="","",E37-G37)
F38: =IF(D38="","",IF(D38="Fiverr",'01_Setup'!B11,IF(D38="Gumroad",'01_Setup'!B12,IF(D38="Payhip",'01_Setup'!B13,IF(D38="Frilans Finans",'01_Setup'!B10,0))))) | G38: =IF(E38="","",E38*F38) | H38: =IF(E38="","",E38-G38)
F39: =IF(D39="","",IF(D39="Fiverr",'01_Setup'!B11,IF(D39="Gumroad",'01_Setup'!B12,IF(D39="Payhip",'01_Setup'!B13,IF(D39="Frilans Finans",'01_Setup'!B10,0))))) | G39: =IF(E39="","",E39*F39) | H39: =IF(E39="","",E39-G39)
F40: =IF(D40="","",IF(D40="Fiverr",'01_Setup'!B11,IF(D40="Gumroad",'01_Setup'!B12,IF(D40="Payhip",'01_Setup'!B13,IF(D40="Frilans Finans",'01_Setup'!B10,0))))) | G40: =IF(E40="","",E40*F40) | H40: =IF(E40="","",E40-G40)
F41: =IF(D41="","",IF(D41="Fiverr",'01_Setup'!B11,IF(D41="Gumroad",'01_Setup'!B12,IF(D41="Payhip",'01_Setup'!B13,IF(D41="Frilans Finans",'01_Setup'!B10,0))))) | G41: =IF(E41="","",E41*F41) | H41: =IF(E41="","",E41-G41)
...

Sheet 05_Expense_Log
A1: Expense log — every budget hit
A3: Date | B3: Vendor | C3: Description | D3: Category | E3: Amount SEK | F3: Status | G3: Evidence | H3: Notes
A55: Paid total | E55: =SUMIF(F4:F53,"Paid",E4:E53)

Sheet 06_Cashflow
A1: 30-day cashflow planner
A3: Day | B3: Date | C3: Inflows SEK | D3: Outflows SEK | E3: Net SEK | F3: Running balance
A4: 0 | B4: Start | C4: 0 | D4: 0 | E4: =C4-D4 | F4: ='01_Setup'!B16+E4
A5: 1 | B5: =IF(B4="Start","",B4) | E5: =C5-D5 | F5: =F4+E5
A6: 2 | B6: =IF(B4="Start","",B4) | E6: =C6-D6 | F6: =F5+E6
A7: 3 | B7: =IF(B4="Start","",B4) | E7: =C7-D7 | F7: =F6+E7
A8: 4 | B8: =IF(B4="Start","",B4) | E8: =C8-D8 | F8: =F7+E8
A9: 5 | B9: =IF(B4="Start","",B4) | E9: =C9-D9 | F9: =F8+E9
A10: 6 | B10: =IF(B4="Start","",B4) | E10: =C10-D10 | F10: =F9+E10
A11: 7 | B11: =IF(B4="Start","",B4) | E11: =C11-D11 | F11: =F10+E11
A12: 8 | B12: =IF(B4="Start","",B4) | E12: =C12-D12 | F12: =F11+E12
A13: 9 | B13: =IF(B4="Start","",B4) | E13: =C13-D13 | F13: =F12+E13
A14: 10 | B14: =IF(B4="Start","",B4) | E14: =C14-D14 | F14: =F13+E14
A15: 11 | B15: =IF(B4="Start","",B4) | E15: =C15-D15 | F15: =F14+E15
A16: 12 | B16: =IF(B4="Start","",B4) | E16: =C16-D16 | F16: =F15+E16
A17: 13 | B17: =IF(B4="Start","",B4) | E17: =C17-D17 | F17: =F16+E17
A18: 14 | B18: =IF(B4="Start","",B4) | E18: =C18-D18 | F18: =F17+E18
A19: 15 | B19: =IF(B4="Start","",B4) | E19: =C19-D19 | F19: =F18+E19
A20: 16 | B20: =IF(B4="Start","",B4) | E20: =C20-D20 | F20: =F19+E20
A21: 17 | B21: =IF(B4="Start","",B4) | E21: =C21-D21 | F21: =F20+E21
A22: 18 | B22: =IF(B4="Start","",B4) | E22: =C22-D22 | F22: =F21+E22
A23: 19 | B23: =IF(B4="Start","",B4) | E23: =C23-D23 | F23: =F22+E23
A24: 20 | B24: =IF(B4="Start","",B4) | E24: =C24-D24 | F24: =F23+E24
A25: 21 | B25: =IF(B4="Start","",B4) | E25: =C25-D25 | F25: =F24+E25
A26: 22 | B26: =IF(B4="Start","",B4) | E26: =C26-D26 | F26: =F25+E26
A27: 23 | B27: =IF(B4="Start","",B4) | E27: =C27-D27 | F27: =F26+E27
A28: 24 | B28: =IF(B4="Start","",B4) | E28: =C28-D28 | F28: =F27+E28
A29: 25 | B29: =IF(B4="Start","",B4) | E29: =C29-D29 | F29: =F28+E29
A30: 26 | B30: =IF(B4="Start","",B4) | E30: =C30-D30 | F30: =F29+E30
A31: 27 | B31: =IF(B4="Start","",B4) | E31: =C31-D31 | F31: =F30+E31
A32: 28 | B32: =IF(B4="Start","",B4) | E32: =C32-D32 | F32: =F31+E32
A33: 29 | B33: =IF(B4="Start","",B4) | E33: =C33-D33 | F33: =F32+E33
A34: 30 | B34: =IF(B4="Start","",B4) | E34: =C34-D34 | F34: =F33+E34

Sheet 07_Invoice_Log
A1: Invoice / offer log
A3: Invoice # | B3: Date | C3: Customer | D3: Description | E3: Amount ex VAT | F3: VAT | G3: Total | H3: Due date | I3: Paid? | J3: Channel
A4: =IF(C4="","",CONCATENATE("INV-",TEXT(1,"000"))) | F4: =IF(E4="","",IF('01_Setup'!B14="Ja",E4*'01_Setup'!B15,0)) | G4: =IF(E4="","",E4+F4)
A5: =IF(C5="","",CONCATENATE("INV-",TEXT(2,"000"))) | F5: =IF(E5="","",IF('01_Setup'!B14="Ja",E5*'01_Setup'!B15,0)) | G5: =IF(E5="","",E5+F5)
A6: =IF(C6="","",CONCATENATE("INV-",TEXT(3,"000"))) | F6: =IF(E6="","",IF('01_Setup'!B14="Ja",E6*'01_Setup'!B15,0)) | G6: =IF(E6="","",E6+F6)
A7: =IF(C7="","",CONCATENATE("INV-",TEXT(4,"000"))) | F7: =IF(E7="","",IF('01_Setup'!B14="Ja",E7*'01_Setup'!B15,0)) | G7: =IF(E7="","",E7+F7)
A8: =IF(C8="","",CONCATENATE("INV-",TEXT(5,"000"))) | F8: =IF(E8="","",IF('01_Setup'!B14="Ja",E8*'01_Setup'!B15,0)) | G8: =IF(E8="","",E8+F8)
A9: =IF(C9="","",CONCATENATE("INV-",TEXT(6,"000"))) | F9: =IF(E9="","",IF('01_Setup'!B14="Ja",E9*'01_Setup'!B15,0)) | G9: =IF(E9="","",E9+F9)
A10: =IF(C10="","",CONCATENATE("INV-",TEXT(7,"000"))) | F10: =IF(E10="","",IF('01_Setup'!B14="Ja",E10*'01_Setup'!B15,0)) | G10: =IF(E10="","",E10+F10)
A11: =IF(C11="","",CONCATENATE("INV-",TEXT(8,"000"))) | F11: =IF(E11="","",IF('01_Setup'!B14="Ja",E11*'01_Setup'!B15,0)) | G11: =IF(E11="","",E11+F11)
A12: =IF(C12="","",CONCATENATE("INV-",TEXT(9,"000"))) | F12: =IF(E12="","",IF('01_Setup'!B14="Ja",E12*'01_Setup'!B15,0)) | G12: =IF(E12="","",E12+F12)
A13: =IF(C13="","",CONCATENATE("INV-",TEXT(10,"000"))) | F13: =IF(E13="","",IF('01_Setup'!B14="Ja",E13*'01_Setup'!B15,0)) | G13: =IF(E13="","",E13+F13)
A14: =IF(C14="","",CONCATENATE("INV-",TEXT(11,"000"))) | F14: =IF(E14="","",IF('01_Setup'!B14="Ja",E14*'01_Setup'!B15,0)) | G14: =IF(E14="","",E14+F14)
A15: =IF(C15="","",CONCATENATE("INV-",TEXT(12,"000"))) | F15: =IF(E15="","",IF('01_Setup'!B14="Ja",E15*'01_Setup'!B15,0)) | G15: =IF(E15="","",E15+F15)
A16: =IF(C16="","",CONCATENATE("INV-",TEXT(13,"000"))) | F16: =IF(E16="","",IF('01_Setup'!B14="Ja",E16*'01_Setup'!B15,0)) | G16: =IF(E16="","",E16+F16)
A17: =IF(C17="","",CONCATENATE("INV-",TEXT(14,"000"))) | F17: =IF(E17="","",IF('01_Setup'!B14="Ja",E17*'01_Setup'!B15,0)) | G17: =IF(E17="","",E17+F17)
A18: =IF(C18="","",CONCATENATE("INV-",TEXT(15,"000"))) | F18: =IF(E18="","",IF('01_Setup'!B14="Ja",E18*'01_Setup'!B15,0)) | G18: =IF(E18="","",E18+F18)
A19: =IF(C19="","",CONCATENATE("INV-",TEXT(16,"000"))) | F19: =IF(E19="","",IF('01_Setup'!B14="Ja",E19*'01_Setup'!B15,0)) | G19: =IF(E19="","",E19+F19)
A20: =IF(C20="","",CONCATENATE("INV-",TEXT(17,"000"))) | F20: =IF(E20="","",IF('01_Setup'!B14="Ja",E20*'01_Setup'!B15,0)) | G20: =IF(E20="","",E20+F20)
A21: =IF(C21="","",CONCATENATE("INV-",TEXT(18,"000"))) | F21: =IF(E21="","",IF('01_Setup'!B14="Ja",E21*'01_Setup'!B15,0)) | G21: =IF(E21="","",E21+F21)
A22: =IF(C22="","",CONCATENATE("INV-",TEXT(19,"000"))) | F22: =IF(E22="","",IF('01_Setup'!B14="Ja",E22*'01_Setup'!B15,0)) | G22: =IF(E22="","",E22+F22)
A23: =IF(C23="","",CONCATENATE("INV-",TEXT(20,"000"))) | F23: =IF(E23="","",IF('01_Setup'!B14="Ja",E23*'01_Setup'!B15,0)) | G23: =IF(E23="","",E23+F23)
A24: =IF(C24="","",CONCATENATE("INV-",TEXT(21,"000"))) | F24: =IF(E24="","",IF('01_Setup'!B14="Ja",E24*'01_Setup'!B15,0)) | G24: =IF(E24="","",E24+F24)
A25: =IF(C25="","",CONCATENATE("INV-",TEXT(22,"000"))) | F25: =IF(E25="","",IF('01_Setup'!B14="Ja",E25*'01_Setup'!B15,0)) | G25: =IF(E25="","",E25+F25)
A26: =IF(C26="","",CONCATENATE("INV-",TEXT(23,"000"))) | F26: =IF(E26="","",IF('01_Setup'!B14="Ja",E26*'01_Setup'!B15,0)) | G26: =IF(E26="","",E26+F26)
A27: =IF(C27="","",CONCATENATE("INV-",TEXT(24,"000"))) | F27: =IF(E27="","",IF('01_Setup'!B14="Ja",E27*'01_Setup'!B15,0)) | G27: =IF(E27="","",E27+F27)
A28: =IF(C28="","",CONCATENATE("INV-",TEXT(25,"000"))) | F28: =IF(E28="","",IF('01_Setup'!B14="Ja",E28*'01_Setup'!B15,0)) | G28: =IF(E28="","",E28+F28)
A29: =IF(C29="","",CONCATENATE("INV-",TEXT(26,"000"))) | F29: =IF(E29="","",IF('01_Setup'!B14="Ja",E29*'01_Setup'!B15,0)) | G29: =IF(E29="","",E29+F29)
A30: =IF(C30="","",CONCATENATE("INV-",TEXT(27,"000"))) | F30: =IF(E30="","",IF('01_Setup'!B14="Ja",E30*'01_Setup'!B15,0)) | G30: =IF(E30="","",E30+F30)
A31: =IF(C31="","",CONCATENATE("INV-",TEXT(28,"000"))) | F31: =IF(E31="","",IF('01_Setup'!B14="Ja",E31*'01_Setup'!B15,0)) | G31: =IF(E31="","",E31+F31)
A32: =IF(C32="","",CONCATENATE("INV-",TEXT(29,"000"))) | F32: =IF(E32="","",IF('01_Setup'!B14="Ja",E32*'01_Setup'!B15,0)) | G32: =IF(E32="","",E32+F32)
A33: =IF(C33="","",CONCATENATE("INV-",TEXT(30,"000"))) | F33: =IF(E33="","",IF('01_Setup'!B14="Ja",E33*'01_Setup'!B15,0)) | G33: =IF(E33="","",E33+F33)

Sheet 08_Tax_Estimate
A1: Illustrative tax / take-home estimate — NOT advice
A3: Warning | B3: These figures are planning illustrations only. Swedish tax depends on municipality, deductions, whether you are employee via egenanställning, F-skatt, VAT, and more. Use an accountant or Skatteverket tools for real decisions.
A5: Settled gross income (from Income_Log) | B5: ='04_Income_Log'!E55
A6: Settled platform fees | B6: ='04_Income_Log'!G55
A7: Settled net before income tax | B7: ='04_Income_Log'!H55
A8: Paid expenses | B8: ='05_Expense_Log'!E55
A9: Illustrative taxable base | B9: =MAX(0,B7-B8)
A10: Illustrative income tax % | B10: ='01_Setup'!B8
A11: Illustrative tax | B11: =B9*B10
A12: Illustrative take-home | B12: =B9-B11

Sheet 09_Dashboard
A1: Dashboard — weekly review
A2: Metric | B2: SEK
A3: Starting / tracked cash (Setup) | B3: ='01_Setup'!B16
A4: Settled revenue net of platform fees | B4: ='04_Income_Log'!H55
A5: Pending revenue net | B5: ='04_Income_Log'!H56
A6: Paid expenses | B6: ='05_Expense_Log'!E55
A7: Implied cash if pending ignores holds | B7: =B3+B4-B6
A8: Illustrative take-home | B8: ='08_Tax_Estimate'!B12
A9: Open invoices total | B9: =SUMIF('07_Invoice_Log'!I4:I33,"No",'07_Invoice_Log'!G4:G33)
A11: Weekly checklist
A12: ☐ Update Income_Log statuses (Pending → Settled only when withdrawable)
A13: ☐ Log every expense the day it hits
A14: ☐ Re-price next offers using Pricing sheet fee logic
A15: ☐ Chase unpaid invoices > 7 days
A16: ☐ Do not count pending marketplace clears as race score
